Workbook

Sheet 26414_編集版
A1: =IF(ISODD(INT((B$1 - '特殊配信マスタ'!$A$1)/7)), "隔週B", "隔週A") -> 隔週A | B1: 46126 | G1: =B1+1 -> 46127 | L1: =G1+1 -> 46128 | Q1: =L1+1 -> 46129 | V1: =Q1+1 -> 46130 | AA1: =V1+1 -> 46131 | AF1: =AA1+1 -> 46132
A2: =MOD(INT((B$1 - '特殊配信マスタ'!$A$1)/7), 3) + 1 -> 1 | B2: メルマガ内容 | C2: 通数 | D2: 設定者 | E2: 確認者 | F2: 計 | G2: メルマガ内容 | H2: 通数 | I2: 設定者 | J2: 確認者 | K2: 計 | L2: メルマガ内容 | M2: 通数 | N2: 設定者 | O2: 確認者 | P2: 計 | Q2: メルマガ内容 | R2: 通数 | S2: 設定者 | T2: 確認者 | U2: 計 | V2: メルマガ内容 | W2: 通数 | X2: 設定者 | Y2: 確認者 | Z2: 計 | AA2: メルマガ内容 | AB2: 通数 | AC2: 設定者 | AD2: 確認者 | AE2: 計 | AF2: メルマガ内容 | AG2: 通数 | AH2: 設定者 | AI2: 確認者 | AJ2: 計
A3: 8 | B3: =IFERROR(__xludf.DUMMYFUNCTION("IFERROR(LET( day, TEXT(B$1, ""ddd""), hour, LOOKUP(2, 1/($A3<>""""), $A3), type_A, $A$1, list_data, IFERROR(FILTER({'リスト'!$E$4:$F142, 'リスト'!$O$4:$P142}, ('リスト'!$A$4:$A142=day)*('リスト'!$B$4:$B142=hour)*(('リスト'!$G$4:$G142=""毎週配信"")+('リスト'!$G$4:$G142="&"type_A))), {"""","""","""",""""}), new_data, IFERROR(FILTER({'新規'!$E$2:$F142, '新規'!$O$2:$P142}, ('新規'!$A$2:$A142=B$1)*('新規'!$B$2:$B142=hour)), {"""","""","""",""""}), special_data, IFERROR(FILTER({'特殊配信マスタ'!$E$2:$F142, '特殊配信マスタ'!$O$2:$P142}, ('特殊配信マスタ"&"'!$A$2:$A142=day)*('特殊配信マスタ'!$B$2:$B142=hour)*('特殊配信マスタ'!$R$2:$R142='特殊配信マスタ'!$S$2:$S142)), {"""","""","""",""""}), combined, VSTACK(list_data, new_data, special_data), FILTER(combined, INDEX(combined, , 1)<>"""", INDEX(combined, , 1)<>0) ), """")"),"関西_自己PR不要_リモート未経験_事務") -> 関西_自己PR不要_リモート未経験_事務 | C3: =IFERROR(__xludf.DUMMYFUNCTION("""COMPUTED_VALUE"""),0.2) -> 0.2 | D3: =IFERROR(__xludf.DUMMYFUNCTION("""COMPUTED_VALUE"""),"R") -> R | F3: =SUM(C3:C12) -> 10.8 | G3: =IFERROR(__xludf.DUMMYFUNCTION("IFERROR(LET( day, TEXT(G$1, ""ddd""), hour, LOOKUP(2, 1/($A3<>""""), $A3), type_A, $A$1, list_data, IFERROR(FILTER({'リスト'!$E$4:$F142, 'リスト'!$O$4:$P142}, ('リスト'!$A$4:$A142=day)*('リスト'!$B$4:$B142=hour)*(('リスト'!$G$4:$G142=""毎週配信"")+('リスト'!$G$4:$G142="&"type_A))), {"""","""","""",""""}), new_data, IFERROR(FILTER({'新規'!$E$2:$F142, '新規'!$O$2:$P142}, ('新規'!$A$2:$A142=G$1)*('新規'!$B$2:$B142=hour)), {"""","""","""",""""}), special_data, IFERROR(FILTER({'特殊配信マスタ'!$E$2:$F142, '特殊配信マスタ'!$O$2:$P142}, ('特殊配信マスタ"&"'!$A$2:$A142=day)*('特殊配信マスタ'!$B$2:$B142=hour)*('特殊配信マスタ'!$R$2:$R142='特殊配信マスタ'!$S$2:$S142)), {"""","""","""",""""}), combined, VSTACK(list_data, new_data, special_data), FILTER(combined, INDEX(combined, , 1)<>"""", INDEX(combined, , 1)<>0) ), """")"),"★求人特集(35歳未満) A") -> ★求人特集(35歳未満) A | H3: =IFERROR(__xludf.DUMMYFUNCTION("""COMPUTED_VALUE"""),7.0) -> 7 | I3: =IFERROR(__xludf.DUMMYFUNCTION("""COMPUTED_VALUE"""),"平") -> 平 | J3: =IFERROR(__xludf.DUMMYFUNCTION("""COMPUTED_VALUE"""),"荒") -> 荒 | K3: =SUM(H3:H12) -> 7.5 | L3: =IFERROR(__xludf.DUMMYFUNCTION("IFERROR(LET( day, TEXT(L$1, ""ddd""), hour, LOOKUP(2, 1/($A3<>""""), $A3), type_A, $A$1, list_data, IFERROR(FILTER({'リスト'!$E$4:$F142, 'リスト'!$O$4:$P142}, ('リスト'!$A$4:$A142=day)*('リスト'!$B$4:$B142=hour)*(('リスト'!$G$4:$G142=""毎週配信"")+('リスト'!$G$4:$G142="&"type_A))), {"""","""","""",""""}), new_data, IFERROR(FILTER({'新規'!$E$2:$F142, '新規'!$O$2:$P142}, ('新規'!$A$2:$A142=L$1)*('新規'!$B$2:$B142=hour)), {"""","""","""",""""}), special_data, IFERROR(FILTER({'特殊配信マスタ'!$E$2:$F142, '特殊配信マスタ'!$O$2:$P142}, ('特殊配信マスタ"&"'!$A$2:$A142=day)*('特殊配信マスタ'!$B$2:$B142=hour)*('特殊配信マスタ'!$R$2:$R142='特殊配信マスタ'!$S$2:$S142)), {"""","""","""",""""}), combined, VSTACK(list_data, new_data, special_data), FILTER(combined, INDEX(combined, , 1)<>"""", INDEX(combined, , 1)<>0) ), """")"),"年収500万以上_未経験歓迎") -> 年収500万以上_未経験歓迎 | M3: =IFERROR(__xludf.DUMMYFUNCTION("""COMPUTED_VALUE"""),0.6) -> 0.6 | N3: =IFERROR(__xludf.DUMMYFUNCTION("""COMPUTED_VALUE"""),"R") -> R | P3: =SUM(M3:M12) -> 5.6 | Q3: =IFERROR(__xludf.DUMMYFUNCTION("IFERROR(LET( day, TEXT(Q$1, ""ddd""), hour, LOOKUP(2, 1/($A3<>""""), $A3), type_A, $A$1, list_data, IFERROR(FILTER({'リスト'!$E$4:$F142, 'リスト'!$O$4:$P142}, ('リスト'!$A$4:$A142=day)*('リスト'!$B$4:$B142=hour)*(('リスト'!$G$4:$G142=""毎週配信"")+('リスト'!$G$4:$G142="&"type_A))), {"""","""","""",""""}), new_data, IFERROR(FILTER({'新規'!$E$2:$F142, '新規'!$O$2:$P142}, ('新規'!$A$2:$A142=Q$1)*('新規'!$B$2:$B142=hour)), {"""","""","""",""""}), special_data, IFERROR(FILTER({'特殊配信マスタ'!$E$2:$F142, '特殊配信マスタ'!$O$2:$P142}, ('特殊配信マスタ"&"'!$A$2:$A142=day)*('特殊配信マスタ'!$B$2:$B142=hour)*('特殊配信マスタ'!$R$2:$R142='特殊配信マスタ'!$S$2:$S142)), {"""","""","""",""""}), combined, VSTACK(list_data, new_data, special_data), FILTER(combined, INDEX(combined, , 1)<>"""", INDEX(combined, , 1)<>0) ), """")"),"データ入力×リモートOK") -> データ入力×リモートOK | R3: =IFERROR(__xludf.DUMMYFUNCTION("""COMPUTED_VALUE"""),1.8) -> 1.8 | S3: =IFERROR(__xludf.DUMMYFUNCTION("""COMPUTED_VALUE"""),"R") -> R | U3: =SUM(R3:R12) -> 9.2 | V3: =IFERROR(__xludf.DUMMYFUNCTION("IFERROR(LET( day, TEXT(V$1, ""ddd""), hour, LOOKUP(2, 1/($A3<>""""), $A3), type_A, $A$1, list_data, IFERROR(FILTER({'リスト'!$E$4:$F142, 'リスト'!$O$4:$P142}, ('リスト'!$A$4:$A142=day)*('リスト'!$B$4:$B142=hour)*(('リスト'!$G$4:$G142=""毎週配信"")+('リスト'!$G$4:$G142="&"type_A))), {"""","""","""",""""}), new_data, IFERROR(FILTER({'新規'!$E$2:$F142, '新規'!$O$2:$P142}, ('新規'!$A$2:$A142=V$1)*('新規'!$B$2:$B142=hour)), {"""","""","""",""""}), special_data, IFERROR(FILTER({'特殊配信マスタ'!$E$2:$F142, '特殊配信マスタ'!$O$2:$P142}, ('特殊配信マスタ"&"'!$A$2:$A142=day)*('特殊配信マスタ'!$B$2:$B142=hour)*('特殊配信マスタ'!$R$2:$R142='特殊配信マスタ'!$S$2:$S142)), {"""","""","""",""""}), combined, VSTACK(list_data, new_data, special_data), FILTER(combined, INDEX(combined, , 1)<>"""", INDEX(combined, , 1)<>0) ), """")"),"★求人特集(35歳未満） B") -> ★求人特集(35歳未満） B | W3: =IFERROR(__xludf.DUMMYFUNCTION("""COMPUTED_VALUE"""),7.0) -> 7 | X3: =IFERROR(__xludf.DUMMYFUNCTION("""COMPUTED_VALUE"""),"平") -> 平 | Y3: =IFERROR(__xludf.DUMMYFUNCTION("""COMPUTED_VALUE"""),"荒") -> 荒 | Z3: =SUM(W3:W12) -> 7.1 | AA3: =IFERROR(__xludf.DUMMYFUNCTION("IFERROR(LET( day, TEXT(AA$1, ""ddd""), hour, LOOKUP(2, 1/($A3<>""""), $A3), type_A, $A$1, list_data, IFERROR(FILTER({'リスト'!$E$4:$F142, 'リスト'!$O$4:$P142}, ('リスト'!$A$4:$A142=day)*('リスト'!$B$4:$B142=hour)*(('リスト'!$G$4:$G142=""毎週配信"")+('リスト'!$G$4:$G142"&"=type_A))), {"""","""","""",""""}), new_data, IFERROR(FILTER({'新規'!$E$2:$F142, '新規'!$O$2:$P142}, ('新規'!$A$2:$A142=AA$1)*('新規'!$B$2:$B142=hour)), {"""","""","""",""""}), special_data, IFERROR(FILTER({'特殊配信マスタ'!$E$2:$F142, '特殊配信マスタ'!$O$2:$P142}, ('特殊配信マ"&"スタ'!$A$2:$A142=day)*('特殊配信マスタ'!$B$2:$B142=hour)*('特殊配信マスタ'!$R$2:$R142='特殊配信マスタ'!$S$2:$S142)), {"""","""","""",""""}), combined, VSTACK(list_data, new_data, special_data), FILTER(combined, INDEX(combined, , 1)<>"""", INDEX(combined, , 1)<>0) ), """")"),"40代再就職") -> 40代再就職 | AB3: =IFERROR(__xludf.DUMMYFUNCTION("""COMPUTED_VALUE"""),0.9) -> 0.9 | AC3: =IFERROR(__xludf.DUMMYFUNCTION("""COMPUTED_VALUE"""),"R") -> R | AE3: =SUM(AB3:AB12) -> 2 | AF3: =IFERROR(__xludf.DUMMYFUNCTION("IFERROR(LET( day, TEXT(AF$1, ""ddd""), hour, LOOKUP(2, 1/($A3<>""""), $A3), type_A, $A$1, list_data, IFERROR(FILTER({'リスト'!$E$4:$F142, 'リスト'!$O$4:$P142}, ('リスト'!$A$4:$A142=day)*('リスト'!$B$4:$B142=hour)*(('リスト'!$G$4:$G142=""毎週配信"")+('リスト'!$G$4:$G142"&"=type_A))), {"""","""","""",""""}), new_data, IFERROR(FILTER({'新規'!$E$2:$F142, '新規'!$O$2:$P142}, ('新規'!$A$2:$A142=AF$1)*('新規'!$B$2:$B142=hour)), {"""","""","""",""""}), special_data, IFERROR(FILTER({'特殊配信マスタ'!$E$2:$F142, '特殊配信マスタ'!$O$2:$P142}, ('特殊配信マ"&"スタ'!$A$2:$A142=day)*('特殊配信マスタ'!$B$2:$B142=hour)*('特殊配信マスタ'!$R$2:$R142='特殊配信マスタ'!$S$2:$S142)), {"""","""","""",""""}), combined, VSTACK(list_data, new_data, special_data), FILTER(combined, INDEX(combined, , 1)<>"""", INDEX(combined, , 1)<>0) ), """")"),"◇掲載終了前+UP_35歳以上 B") -> ◇掲載終了前+UP_35歳以上 B | AG3: =IFERROR(__xludf.DUMMYFUNCTION("""COMPUTED_VALUE"""),1.0) -> 1 | AH3: =IFERROR(__xludf.DUMMYFUNCTION("""COMPUTED_VALUE"""),"内") -> 内 | AI3: =IFERROR(__xludf.DUMMYFUNCTION("""COMPUTED_VALUE"""),"荒") -> 荒 | AJ3: =SUM(AG3:AG12) -> 8.9
B4: =IFERROR(__xludf.DUMMYFUNCTION("""COMPUTED_VALUE"""),"応募から1日_好条件営業ランキング") -> 応募から1日_好条件営業ランキング | C4: =IFERROR(__xludf.DUMMYFUNCTION("""COMPUTED_VALUE"""),0.1) -> 0.1 | D4: =IFERROR(__xludf.DUMMYFUNCTION("""COMPUTED_VALUE"""),"R") -> R | G4: =IFERROR(__xludf.DUMMYFUNCTION("""COMPUTED_VALUE"""),"50代事務") -> 50代事務 | H4: =IFERROR(__xludf.DUMMYFUNCTION("""COMPUTED_VALUE"""),0.4) -> 0.4 | I4: =IFERROR(__xludf.DUMMYFUNCTION("""COMPUTED_VALUE"""),"部") -> 部 | J4: =IFERROR(__xludf.DUMMYFUNCTION("""COMPUTED_VALUE"""),"石") -> 石 | L4: =IFERROR(__xludf.DUMMYFUNCTION("""COMPUTED_VALUE"""),"応募から1日_好条件営業ランキング") -> 応募から1日_好条件営業ランキング | M4: =IFERROR(__xludf.DUMMYFUNCTION("""COMPUTED_VALUE"""),0.1) -> 0.1 | N4: =IFERROR(__xludf.DUMMYFUNCTION("""COMPUTED_VALUE"""),"R") -> R | Q4: =IFERROR(__xludf.DUMMYFUNCTION("""COMPUTED_VALUE"""),"フルリモート×好条件") -> フルリモート×好条件 | R4: =IFERROR(__xludf.DUMMYFUNCTION("""COMPUTED_VALUE"""),5.7) -> 5.7 | S4: =IFERROR(__xludf.DUMMYFUNCTION("""COMPUTED_VALUE"""),"部") -> 部 | T4: =IFERROR(__xludf.DUMMYFUNCTION("""COMPUTED_VALUE"""),"石") -> 石 | V4: =IFERROR(__xludf.DUMMYFUNCTION("""COMPUTED_VALUE"""),"応募から1日_好条件営業ランキング") -> 応募から1日_好条件営業ランキング | W4: =IFERROR(__xludf.DUMMYFUNCTION("""COMPUTED_VALUE"""),0.1) -> 0.1 | X4: =IFERROR(__xludf.DUMMYFUNCTION("""COMPUTED_VALUE"""),"R") -> R | AA4: =IFERROR(__xludf.DUMMYFUNCTION("""COMPUTED_VALUE"""),"40代再就職_関西") -> 40代再就職_関西 | AB4: =IFERROR(__xludf.DUMMYFUNCTION("""COMPUTED_VALUE"""),0.4) -> 0.4 | AC4: =IFERROR(__xludf.DUMMYFUNCTION("""COMPUTED_VALUE"""),"R") -> R | AF4: =IFERROR(__xludf.DUMMYFUNCTION("""COMPUTED_VALUE"""),"◇掲載終了前+UP_関西 B") -> ◇掲載終了前+UP_関西 B | AG4: =IFERROR(__xludf.DUMMYFUNCTION("""COMPUTED_VALUE"""),1.0) -> 1 | AH4: =IFERROR(__xludf.DUMMYFUNCTION("""COMPUTED_VALUE"""),"内") -> 内 | AI4: =IFERROR(__xludf.DUMMYFUNCTION("""COMPUTED_VALUE"""),"荒") -> 荒
B5: =IFERROR(__xludf.DUMMYFUNCTION("""COMPUTED_VALUE"""),"快適な在宅ワーク") -> 快適な在宅ワーク | C5: =IFERROR(__xludf.DUMMYFUNCTION("""COMPUTED_VALUE"""),4.3) -> 4.3 | D5: =IFERROR(__xludf.DUMMYFUNCTION("""COMPUTED_VALUE"""),"石") -> 石 | E5: =IFERROR(__xludf.DUMMYFUNCTION("""COMPUTED_VALUE"""),"部") -> 部 | G5: =IFERROR(__xludf.DUMMYFUNCTION("""COMPUTED_VALUE"""),"応募から1日_好条件営業ランキング") -> 応募から1日_好条件営業ランキング | H5: =IFERROR(__xludf.DUMMYFUNCTION("""COMPUTED_VALUE"""),0.1) -> 0.1 | I5: =IFERROR(__xludf.DUMMYFUNCTION("""COMPUTED_VALUE"""),"R") -> R | L5: =IFERROR(__xludf.DUMMYFUNCTION("""COMPUTED_VALUE"""),"新着_クリエイティブ") -> 新着_クリエイティブ | M5: =IFERROR(__xludf.DUMMYFUNCTION("""COMPUTED_VALUE"""),0.4) -> 0.4 | N5: =IFERROR(__xludf.DUMMYFUNCTION("""COMPUTED_VALUE"""),"R") -> R | Q5: =IFERROR(__xludf.DUMMYFUNCTION("""COMPUTED_VALUE"""),"応募から1日_好条件営業ランキング") -> 応募から1日_好条件営業ランキング | R5: =IFERROR(__xludf.DUMMYFUNCTION("""COMPUTED_VALUE"""),0.1) -> 0.1 | S5: =IFERROR(__xludf.DUMMYFUNCTION("""COMPUTED_VALUE"""),"R") -> R | AA5: =IFERROR(__xludf.DUMMYFUNCTION("""COMPUTED_VALUE"""),"応募から1日_好条件営業ランキング") -> 応募から1日_好条件営業ランキング | AB5: =IFERROR(__xludf.DUMMYFUNCTION("""COMPUTED_VALUE"""),0.1) -> 0.1 | AC5: =IFERROR(__xludf.DUMMYFUNCTION("""COMPUTED_VALUE"""),"R") -> R | AF5: =IFERROR(__xludf.DUMMYFUNCTION("""COMPUTED_VALUE"""),"webデザイナー×未経験歓迎_希望") -> webデザイナー×未経験歓迎_希望 | AG5: =IFERROR(__xludf.DUMMYFUNCTION("""COMPUTED_VALUE"""),0.6) -> 0.6 | AH5: =IFERROR(__xludf.DUMMYFUNCTION("""COMPUTED_VALUE"""),"R") -> R
B6: =IFERROR(__xludf.DUMMYFUNCTION("""COMPUTED_VALUE"""),"推し活_残業なし_休日120日以上_月給30万以上") -> 推し活_残業なし_休日120日以上_月給30万以上 | C6: =IFERROR(__xludf.DUMMYFUNCTION("""COMPUTED_VALUE"""),1.2) -> 1.2 | D6: =IFERROR(__xludf.DUMMYFUNCTION("""COMPUTED_VALUE"""),"R") -> R | L6: =IFERROR(__xludf.DUMMYFUNCTION("""COMPUTED_VALUE"""),"新着_企画営業") -> 新着_企画営業 | M6: =IFERROR(__xludf.DUMMYFUNCTION("""COMPUTED_VALUE"""),0.9) -> 0.9 | N6: =IFERROR(__xludf.DUMMYFUNCTION("""COMPUTED_VALUE"""),"R") -> R | Q6: =IFERROR(__xludf.DUMMYFUNCTION("""COMPUTED_VALUE"""),"既婚者") -> 既婚者 | R6: =IFERROR(__xludf.DUMMYFUNCTION("""COMPUTED_VALUE"""),0.4) -> 0.4 | S6: =IFERROR(__xludf.DUMMYFUNCTION("""COMPUTED_VALUE"""),"R") -> R | AA6: =IFERROR(__xludf.DUMMYFUNCTION("""COMPUTED_VALUE"""),"人気検索KW_事務系希望") -> 人気検索KW_事務系希望 | AB6: =IFERROR(__xludf.DUMMYFUNCTION("""COMPUTED_VALUE"""),0.6) -> 0.6 | AC6: =IFERROR(__xludf.DUMMYFUNCTION("""COMPUTED_VALUE"""),"R") -> R | AF6: =IFERROR(__xludf.DUMMYFUNCTION("""COMPUTED_VALUE"""),"応募から1日_好条件営業ランキング") -> 応募から1日_好条件営業ランキング | AG6: =IFERROR(__xludf.DUMMYFUNCTION("""COMPUTED_VALUE"""),0.1) -> 0.1 | AH6: =IFERROR(__xludf.DUMMYFUNCTION("""COMPUTED_VALUE"""),"R") -> R
B7: =IFERROR(__xludf.DUMMYFUNCTION("""COMPUTED_VALUE"""),"◇ポジションマッチ A1") -> ◇ポジションマッチ A1 | C7: =IFERROR(__xludf.DUMMYFUNCTION("""COMPUTED_VALUE"""),2.5) -> 2.5 | D7: =IFERROR(__xludf.DUMMYFUNCTION("""COMPUTED_VALUE"""),"内") -> 内 | E7: =IFERROR(__xludf.DUMMYFUNCTION("""COMPUTED_VALUE"""),"平") -> 平 | L7: =IFERROR(__xludf.DUMMYFUNCTION("""COMPUTED_VALUE"""),"新着_経理") -> 新着_経理 | M7: =IFERROR(__xludf.DUMMYFUNCTION("""COMPUTED_VALUE"""),0.5) -> 0.5 | N7: =IFERROR(__xludf.DUMMYFUNCTION("""COMPUTED_VALUE"""),"R") -> R | Q7: =IFERROR(__xludf.DUMMYFUNCTION("""COMPUTED_VALUE"""),"梅田で働く") -> 梅田で働く | R7: =IFERROR(__xludf.DUMMYFUNCTION("""COMPUTED_VALUE"""),0.8) -> 0.8 | S7: =IFERROR(__xludf.DUMMYFUNCTION("""COMPUTED_VALUE"""),"R") -> R | AF7: =IFERROR(__xludf.DUMMYFUNCTION("""COMPUTED_VALUE"""),"高収入_リモート_営業") -> 高収入_リモート_営業 | AG7: =IFERROR(__xludf.DUMMYFUNCTION("""COMPUTED_VALUE"""),1.2) -> 1.2 | AH7: =IFERROR(__xludf.DUMMYFUNCTION("""COMPUTED_VALUE"""),"R") -> R
B8: =IFERROR(__xludf.DUMMYFUNCTION("""COMPUTED_VALUE"""),"◇ポジションマッチ_36歳以上 A1") -> ◇ポジションマッチ_36歳以上 A1 | C8: =IFERROR(__xludf.DUMMYFUNCTION("""COMPUTED_VALUE"""),2.5) -> 2.5 | D8: =IFERROR(__xludf.DUMMYFUNCTION("""COMPUTED_VALUE"""),"内") -> 内 | E8: =IFERROR(__xludf.DUMMYFUNCTION("""COMPUTED_VALUE"""),"平") -> 平 | L8: =IFERROR(__xludf.DUMMYFUNCTION("""COMPUTED_VALUE"""),"新着_事務") -> 新着_事務 | M8: =IFERROR(__xludf.DUMMYFUNCTION("""COMPUTED_VALUE"""),2.5) -> 2.5 | N8: =IFERROR(__xludf.DUMMYFUNCTION("""COMPUTED_VALUE"""),"R") -> R | Q8: =IFERROR(__xludf.DUMMYFUNCTION("""COMPUTED_VALUE"""),"未婚者") -> 未婚者 | R8: =IFERROR(__xludf.DUMMYFUNCTION("""COMPUTED_VALUE"""),0.4) -> 0.4 | S8: =IFERROR(__xludf.DUMMYFUNCTION("""COMPUTED_VALUE"""),"R") -> R | AF8: =IFERROR(__xludf.DUMMYFUNCTION("""COMPUTED_VALUE"""),"高収入_リモート_事務") -> 高収入_リモート_事務 | AG8: =IFERROR(__xludf.DUMMYFUNCTION("""COMPUTED_VALUE"""),3.0) -> 3 | AH8: =IFERROR(__xludf.DUMMYFUNCTION("""COMPUTED_VALUE"""),"R") -> R
L9: =IFERROR(__xludf.DUMMYFUNCTION("""COMPUTED_VALUE"""),"新着_人事") -> 新着_人事 | M9: =IFERROR(__xludf.DUMMYFUNCTION("""COMPUTED_VALUE"""),0.6) -> 0.6 | N9: =IFERROR(__xludf.DUMMYFUNCTION("""COMPUTED_VALUE"""),"R") -> R | AF9: =IFERROR(__xludf.DUMMYFUNCTION("""COMPUTED_VALUE"""),"◇掲載終了前+UP B") -> ◇掲載終了前+UP B | AG9: =IFERROR(__xludf.DUMMYFUNCTION("""COMPUTED_VALUE"""),2.0) -> 2 | AH9: =IFERROR(__xludf.DUMMYFUNCTION("""COMPUTED_VALUE"""),"内") -> 内 | AI9: =IFERROR(__xludf.DUMMYFUNCTION("""COMPUTED_VALUE"""),"荒") -> 荒
A13: =A3+1 -> 9 | B13: =IFERROR(__xludf.DUMMYFUNCTION("IFERROR(LET( day, TEXT(B$1, ""ddd""), hour, LOOKUP(2, 1/($A13<>""""), $A13), type_A, $A$1, list_data, IFERROR(FILTER({'リスト'!$E$4:$F142, 'リスト'!$O$4:$P142}, ('リスト'!$A$4:$A142=day)*('リスト'!$B$4:$B142=hour)*(('リスト'!$G$4:$G142=""毎週配信"")+('リスト'!$G$4:$G14"&"2=type_A))), {"""","""","""",""""}), new_data, IFERROR(FILTER({'新規'!$E$2:$F142, '新規'!$O$2:$P142}, ('新規'!$A$2:$A142=B$1)*('新規'!$B$2:$B142=hour)), {"""","""","""",""""}), special_data, IFERROR(FILTER({'特殊配信マスタ'!$E$2:$F142, '特殊配信マスタ'!$O$2:$P142}, ('特殊配信マ"&"スタ'!$A$2:$A142=day)*('特殊配信マスタ'!$B$2:$B142=hour)*('特殊配信マスタ'!$R$2:$R142='特殊配信マスタ'!$S$2:$S142)), {"""","""","""",""""}), combined, VSTACK(list_data, new_data, special_data), FILTER(combined, INDEX(combined, , 1)<>"""", INDEX(combined, , 1)<>0) ), """")"),"ランキング_クリエイティブ（Web）_希望") -> ランキング_クリエイティブ（Web）_希望 | C13: =IFERROR(__xludf.DUMMYFUNCTION("""COMPUTED_VALUE"""),0.5) -> 0.5 | D13: =IFERROR(__xludf.DUMMYFUNCTION("""COMPUTED_VALUE"""),"R") -> R | F13: =SUM(C13:C22) -> 2.5 | G13: =IFERROR(__xludf.DUMMYFUNCTION("IFERROR(LET( day, TEXT(G$1, ""ddd""), hour, LOOKUP(2, 1/($A13<>""""), $A13), type_A, $A$1, list_data, IFERROR(FILTER({'リスト'!$E$4:$F142, 'リスト'!$O$4:$P142}, ('リスト'!$A$4:$A142=day)*('リスト'!$B$4:$B142=hour)*(('リスト'!$G$4:$G142=""毎週配信"")+('リスト'!$G$4:$G14"&"2=type_A))), {"""","""","""",""""}), new_data, IFERROR(FILTER({'新規'!$E$2:$F142, '新規'!$O$2:$P142}, ('新規'!$A$2:$A142=G$1)*('新規'!$B$2:$B142=hour)), {"""","""","""",""""}), special_data, IFERROR(FILTER({'特殊配信マスタ'!$E$2:$F142, '特殊配信マスタ'!$O$2:$P142}, ('特殊配信マ"&"スタ'!$A$2:$A142=day)*('特殊配信マスタ'!$B$2:$B142=hour)*('特殊配信マスタ'!$R$2:$R142='特殊配信マスタ'!$S$2:$S142)), {"""","""","""",""""}), combined, VSTACK(list_data, new_data, special_data), FILTER(combined, INDEX(combined, , 1)<>"""", INDEX(combined, , 1)<>0) ), """")"),"ランキング_エンジニア（IT系）_希望") -> ランキング_エンジニア（IT系）_希望 | H13: =IFERROR(__xludf.DUMMYFUNCTION("""COMPUTED_VALUE"""),0.3) -> 0.3 | I13: =IFERROR(__xludf.DUMMYFUNCTION("""COMPUTED_VALUE"""),"R") -> R | K13: =SUM(H13:H22) -> 3.8 | L13: =IFERROR(__xludf.DUMMYFUNCTION("IFERROR(LET( day, TEXT(L$1, ""ddd""), hour, LOOKUP(2, 1/($A13<>""""), $A13), type_A, $A$1, list_data, IFERROR(FILTER({'リスト'!$E$4:$F142, 'リスト'!$O$4:$P142}, ('リスト'!$A$4:$A142=day)*('リスト'!$B$4:$B142=hour)*(('リスト'!$G$4:$G142=""毎週配信"")+('リスト'!$G$4:$G14"&"2=type_A))), {"""","""","""",""""}), new_data, IFERROR(FILTER({'新規'!$E$2:$F142, '新規'!$O$2:$P142}, ('新規'!$A$2:$A142=L$1)*('新規'!$B$2:$B142=hour)), {"""","""","""",""""}), special_data, IFERROR(FILTER({'特殊配信マスタ'!$E$2:$F142, '特殊配信マスタ'!$O$2:$P142}, ('特殊配信マ"&"スタ'!$A$2:$A142=day)*('特殊配信マスタ'!$B$2:$B142=hour)*('特殊配信マスタ'!$R$2:$R142='特殊配信マスタ'!$S$2:$S142)), {"""","""","""",""""}), combined, VSTACK(list_data, new_data, special_data), FILTER(combined, INDEX(combined, , 1)<>"""", INDEX(combined, , 1)<>0) ), """")"),"ランキング_営業（BtoB）_希望") -> ランキング_営業（BtoB）_希望 | M13: =IFERROR(__xludf.DUMMYFUNCTION("""COMPUTED_VALUE"""),0.3) -> 0.3 | N13: =IFERROR(__xludf.DUMMYFUNCTION("""COMPUTED_VALUE"""),"R") -> R | P13: =SUM(M13:M22) -> 2.3 | Q13: =IFERROR(__xludf.DUMMYFUNCTION("IFERROR(LET( day, TEXT(Q$1, ""ddd""), hour, LOOKUP(2, 1/($A13<>""""), $A13), type_A, $A$1, list_data, IFERROR(FILTER({'リスト'!$E$4:$F142, 'リスト'!$O$4:$P142}, ('リスト'!$A$4:$A142=day)*('リスト'!$B$4:$B142=hour)*(('リスト'!$G$4:$G142=""毎週配信"")+('リスト'!$G$4:$G14"&"2=type_A))), {"""","""","""",""""}), new_data, IFERROR(FILTER({'新規'!$E$2:$F142, '新規'!$O$2:$P142}, ('新規'!$A$2:$A142=Q$1)*('新規'!$B$2:$B142=hour)), {"""","""","""",""""}), special_data, IFERROR(FILTER({'特殊配信マスタ'!$E$2:$F142, '特殊配信マスタ'!$O$2:$P142}, ('特殊配信マ"&"スタ'!$A$2:$A142=day)*('特殊配信マスタ'!$B$2:$B142=hour)*('特殊配信マスタ'!$R$2:$R142='特殊配信マスタ'!$S$2:$S142)), {"""","""","""",""""}), combined, VSTACK(list_data, new_data, special_data), FILTER(combined, INDEX(combined, , 1)<>"""", INDEX(combined, , 1)<>0) ), """")"),"40~60代活躍中") -> 40~60代活躍中 | R13: =IFERROR(__xludf.DUMMYFUNCTION("""COMPUTED_VALUE"""),1.5) -> 1.5 | S13: =IFERROR(__xludf.DUMMYFUNCTION("""COMPUTED_VALUE"""),"石") -> 石 | T13: =IFERROR(__xludf.DUMMYFUNCTION("""COMPUTED_VALUE"""),"武") -> 武 | U13: =SUM(R13:R22) -> 1.9 | V13: =IFERROR(__xludf.DUMMYFUNCTION("IFERROR(LET( day, TEXT(V$1, ""ddd""), hour, LOOKUP(2, 1/($A13<>""""), $A13), type_A, $A$1, list_data, IFERROR(FILTER({'リスト'!$E$4:$F142, 'リスト'!$O$4:$P142}, ('リスト'!$A$4:$A142=day)*('リスト'!$B$4:$B142=hour)*(('リスト'!$G$4:$G142=""毎週配信"")+('リスト'!$G$4:$G14"&"2=type_A))), {"""","""","""",""""}), new_data, IFERROR(FILTER({'新規'!$E$2:$F142, '新規'!$O$2:$P142}, ('新規'!$A$2:$A142=V$1)*('新規'!$B$2:$B142=hour)), {"""","""","""",""""}), special_data, IFERROR(FILTER({'特殊配信マスタ'!$E$2:$F142, '特殊配信マスタ'!$O$2:$P142}, ('特殊配信マ"&"スタ'!$A$2:$A142=day)*('特殊配信マスタ'!$B$2:$B142=hour)*('特殊配信マスタ'!$R$2:$R142='特殊配信マスタ'!$S$2:$S142)), {"""","""","""",""""}), combined, VSTACK(list_data, new_data, special_data), FILTER(combined, INDEX(combined, , 1)<>"""", INDEX(combined, , 1)<>0) ), """")"),"NPS取得アンケート") -> NPS取得アンケート | W13: =IFERROR(__xludf.DUMMYFUNCTION("""COMPUTED_VALUE"""),0.3) -> 0.3 | X13: =IFERROR(__xludf.DUMMYFUNCTION("""COMPUTED_VALUE"""),"R") -> R | Z13: =SUM(W13:W22) -> 2.4 | AA13: =IFERROR(__xludf.DUMMYFUNCTION("IFERROR(LET( day, TEXT(AA$1, ""ddd""), hour, LOOKUP(2, 1/($A13<>""""), $A13), type_A, $A$1, list_data, IFERROR(FILTER({'リスト'!$E$4:$F142, 'リスト'!$O$4:$P142}, ('リスト'!$A$4:$A142=day)*('リスト'!$B$4:$B142=hour)*(('リスト'!$G$4:$G142=""毎週配信"")+('リスト'!$G$4:$G1"&"42=type_A))), {"""","""","""",""""}), new_data, IFERROR(FILTER({'新規'!$E$2:$F142, '新規'!$O$2:$P142}, ('新規'!$A$2:$A142=AA$1)*('新規'!$B$2:$B142=hour)), {"""","""","""",""""}), special_data, IFERROR(FILTER({'特殊配信マスタ'!$E$2:$F142, '特殊配信マスタ'!$O$2:$P142}, ('特殊配"&"信マスタ'!$A$2:$A142=day)*('特殊配信マスタ'!$B$2:$B142=hour)*('特殊配信マスタ'!$R$2:$R142='特殊配信マスタ'!$S$2:$S142)), {"""","""","""",""""}), combined, VSTACK(list_data, new_data, special_data), FILTER(combined, INDEX(combined, , 1)<>"""", INDEX(combined, , 1)<>0) ), """")"),"これから人気×エンジニア") -> これから人気×エンジニア | AB13: =IFERROR(__xludf.DUMMYFUNCTION("""COMPUTED_VALUE"""),0.2) -> 0.2 | AC13: =IFERROR(__xludf.DUMMYFUNCTION("""COMPUTED_VALUE"""),"R") -> R | AE13: =SUM(AB13:AB22) -> 5.8 | AF13: =IFERROR(__xludf.DUMMYFUNCTION("IFERROR(LET( day, TEXT(AF$1, ""ddd""), hour, LOOKUP(2, 1/($A13<>""""), $A13), type_A, $A$1, list_data, IFERROR(FILTER({'リスト'!$E$4:$F142, 'リスト'!$O$4:$P142}, ('リスト'!$A$4:$A142=day)*('リスト'!$B$4:$B142=hour)*(('リスト'!$G$4:$G142=""毎週配信"")+('リスト'!$G$4:$G1"&"42=type_A))), {"""","""","""",""""}), new_data, IFERROR(FILTER({'新規'!$E$2:$F142, '新規'!$O$2:$P142}, ('新規'!$A$2:$A142=AF$1)*('新規'!$B$2:$B142=hour)), {"""","""","""",""""}), special_data, IFERROR(FILTER({'特殊配信マスタ'!$E$2:$F142, '特殊配信マスタ'!$O$2:$P142}, ('特殊配"&"信マスタ'!$A$2:$A142=day)*('特殊配信マスタ'!$B$2:$B142=hour)*('特殊配信マスタ'!$R$2:$R142='特殊配信マスタ'!$S$2:$S142)), {"""","""","""",""""}), combined, VSTACK(list_data, new_data, special_data), FILTER(combined, INDEX(combined, , 1)<>"""", INDEX(combined, , 1)<>0) ), """")"),"年収600万円以上") -> 年収600万円以上 | AG13: =IFERROR(__xludf.DUMMYFUNCTION("""COMPUTED_VALUE"""),0.3) -> 0.3 | AH13: =IFERROR(__xludf.DUMMYFUNCTION("""COMPUTED_VALUE"""),"R") -> R | AJ13: =SUM(AG13:AG22) -> 1.9
B14: =IFERROR(__xludf.DUMMYFUNCTION("""COMPUTED_VALUE"""),"ランキング_営業（マーケ）_希望") -> ランキング_営業（マーケ）_希望 | C14: =IFERROR(__xludf.DUMMYFUNCTION("""COMPUTED_VALUE"""),0.5) -> 0.5 | D14: =IFERROR(__xludf.DUMMYFUNCTION("""COMPUTED_VALUE"""),"R") -> R | G14: =IFERROR(__xludf.DUMMYFUNCTION("""COMPUTED_VALUE"""),"ランキング_クリエイティブ（その他）_希望") -> ランキング_クリエイティブ（その他）_希望 | H14: =IFERROR(__xludf.DUMMYFUNCTION("""COMPUTED_VALUE"""),0.4) -> 0.4 | I14: =IFERROR(__xludf.DUMMYFUNCTION("""COMPUTED_VALUE"""),"R") -> R | L14: =IFERROR(__xludf.DUMMYFUNCTION("""COMPUTED_VALUE"""),"ランキング_事務（秘書）_希望") -> ランキング_事務（秘書）_希望 | M14: =IFERROR(__xludf.DUMMYFUNCTION("""COMPUTED_VALUE"""),0.9) -> 0.9 | N14: =IFERROR(__xludf.DUMMYFUNCTION("""COMPUTED_VALUE"""),"R") -> R | Q14: =IFERROR(__xludf.DUMMYFUNCTION("""COMPUTED_VALUE"""),"ランキング_事務（経理）_希望") -> ランキング_事務（経理）_希望 | R14: =IFERROR(__xludf.DUMMYFUNCTION("""COMPUTED_VALUE"""),0.4) -> 0.4 | S14: =IFERROR(__xludf.DUMMYFUNCTION("""COMPUTED_VALUE"""),"R") -> R | V14: =IFERROR(__xludf.DUMMYFUNCTION("""COMPUTED_VALUE"""),"単独求人訴求メルマガ_A") -> 単独求人訴求メルマガ_A | W14: =IFERROR(__xludf.DUMMYFUNCTION("""COMPUTED_VALUE"""),2.1) -> 2.1 | X14: =IFERROR(__xludf.DUMMYFUNCTION("""COMPUTED_VALUE"""),"武") -> 武 | Y14: =IFERROR(__xludf.DUMMYFUNCTION("""COMPUTED_VALUE"""),"部") -> 部 | AA14: =IFERROR(__xludf.DUMMYFUNCTION("""COMPUTED_VALUE"""),"これから人気×リモート") -> これから人気×リモート | AB14: =IFERROR(__xludf.DUMMYFUNCTION("""COMPUTED_VALUE"""),0.6) -> 0.6 | AC14: =IFERROR(__xludf.DUMMYFUNCTION("""COMPUTED_VALUE"""),"R") -> R | AF14: =IFERROR(__xludf.DUMMYFUNCTION("""COMPUTED_VALUE"""),"ランキング_事務（広報）_希望") -> ランキング_事務（広報）_希望 | AG14: =IFERROR(__xludf.DUMMYFUNCTION("""COMPUTED_VALUE"""),0.3) -> 0.3 | AH14: =IFERROR(__xludf.DUMMYFUNCTION("""COMPUTED_VALUE"""),"R") -> R
B15: =IFERROR(__xludf.DUMMYFUNCTION("""COMPUTED_VALUE"""),"ランキング_事務（一般事務）_希望") -> ランキング_事務（一般事務）_希望 | C15: =IFERROR(__xludf.DUMMYFUNCTION("""COMPUTED_VALUE"""),1.5) -> 1.5 | D15: =IFERROR(__xludf.DUMMYFUNCTION("""COMPUTED_VALUE"""),"R") -> R | G15: =IFERROR(__xludf.DUMMYFUNCTION("""COMPUTED_VALUE"""),"ランキング_営業（その他）_希望") -> ランキング_営業（その他）_希望 | H15: =IFERROR(__xludf.DUMMYFUNCTION("""COMPUTED_VALUE"""),0.4) -> 0.4 | I15: =IFERROR(__xludf.DUMMYFUNCTION("""COMPUTED_VALUE"""),"R") -> R | L15: =IFERROR(__xludf.DUMMYFUNCTION("""COMPUTED_VALUE"""),"関西限定求人特集") -> 関西限定求人特集 | M15: =IFERROR(__xludf.DUMMYFUNCTION("""COMPUTED_VALUE"""),1.1) -> 1.1 | N15: =IFERROR(__xludf.DUMMYFUNCTION("""COMPUTED_VALUE"""),"R") -> R | AA15: =IFERROR(__xludf.DUMMYFUNCTION("""COMPUTED_VALUE"""),"これから人気×リモート×営業") -> これから人気×リモート×営業 | AB15: =IFERROR(__xludf.DUMMYFUNCTION("""COMPUTED_VALUE"""),0.3) -> 0.3 | AC15: =IFERROR(__xludf.DUMMYFUNCTION("""COMPUTED_VALUE"""),"R") -> R | AF15: =IFERROR(__xludf.DUMMYFUNCTION("""COMPUTED_VALUE"""),"直近新規登録会員向け") -> 直近新規登録会員向け | AG15: =IFERROR(__xludf.DUMMYFUNCTION("""COMPUTED_VALUE"""),1.3) -> 1.3 | AH15: =IFERROR(__xludf.DUMMYFUNCTION("""COMPUTED_VALUE"""),"R") -> R
G16: =IFERROR(__xludf.DUMMYFUNCTION("""COMPUTED_VALUE"""),"ランキング_事務（営業事務）_希望") -> ランキング_事務（営業事務）_希望 | H16: =IFERROR(__xludf.DUMMYFUNCTION("""COMPUTED_VALUE"""),1.0) -> 1 | I16: =IFERROR(__xludf.DUMMYFUNCTION("""COMPUTED_VALUE"""),"R") -> R | AA16: =IFERROR(__xludf.DUMMYFUNCTION("""COMPUTED_VALUE"""),"これから人気×販サ") -> これから人気×販サ | AB16: =IFERROR(__xludf.DUMMYFUNCTION("""COMPUTED_VALUE"""),0.2) -> 0.2 | AC16: =IFERROR(__xludf.DUMMYFUNCTION("""COMPUTED_VALUE"""),"R") -> R
G17: =IFERROR(__xludf.DUMMYFUNCTION("""COMPUTED_VALUE"""),"裁量労働制") -> 裁量労働制 | H17: =IFERROR(__xludf.DUMMYFUNCTION("""COMPUTED_VALUE"""),1.1) -> 1.1 | I17: =IFERROR(__xludf.DUMMYFUNCTION("""COMPUTED_VALUE"""),"R") -> R | AA17: =IFERROR(__xludf.DUMMYFUNCTION("""COMPUTED_VALUE"""),"応募ランキング C") -> 応募ランキング C | AB17: =IFERROR(__xludf.DUMMYFUNCTION("""COMPUTED_VALUE"""),4.5) -> 4.5 | AC17: =IFERROR(__xludf.DUMMYFUNCTION("""COMPUTED_VALUE"""),"R") -> R
G18: =IFERROR(__xludf.DUMMYFUNCTION("""COMPUTED_VALUE"""),"時短×リモート") -> 時短×リモート | H18: =IFERROR(__xludf.DUMMYFUNCTION("""COMPUTED_VALUE"""),0.6) -> 0.6 | I18: =IFERROR(__xludf.DUMMYFUNCTION("""COMPUTED_VALUE"""),"R") -> R
A23: =A13+1 -> 10 | B23: =IFERROR(__xludf.DUMMYFUNCTION("IFERROR(LET( day, TEXT(B$1, ""ddd""), hour, LOOKUP(2, 1/($A23<>""""), $A23), type_A, $A$1, list_data, IFERROR(FILTER({'リスト'!$E$4:$F142, 'リスト'!$O$4:$P142}, ('リスト'!$A$4:$A142=day)*('リスト'!$B$4:$B142=hour)*(('リスト'!$G$4:$G142=""毎週配信"")+('リスト'!$G$4:$G14"&"2=type_A))), {"""","""","""",""""}), new_data, IFERROR(FILTER({'新規'!$E$2:$F142, '新規'!$O$2:$P142}, ('新規'!$A$2:$A142=B$1)*('新規'!$B$2:$B142=hour)), {"""","""","""",""""}), special_data, IFERROR(FILTER({'特殊配信マスタ'!$E$2:$F142, '特殊配信マスタ'!$O$2:$P142}, ('特殊配信マ"&"スタ'!$A$2:$A142=day)*('特殊配信マスタ'!$B$2:$B142=hour)*('特殊配信マスタ'!$R$2:$R142='特殊配信マスタ'!$S$2:$S142)), {"""","""","""",""""}), combined, VSTACK(list_data, new_data, special_data), FILTER(combined, INDEX(combined, , 1)<>"""", INDEX(combined, , 1)<>0) ), """")"),"事務_販サ経験者向け_東京") -> 事務_販サ経験者向け_東京 | C23: =IFERROR(__xludf.DUMMYFUNCTION("""COMPUTED_VALUE"""),0.4) -> 0.4 | D23: =IFERROR(__xludf.DUMMYFUNCTION("""COMPUTED_VALUE"""),"R") -> R | F23: =SUM(C23:C32) -> 2.9 | G23: =IFERROR(__xludf.DUMMYFUNCTION("IFERROR(LET( day, TEXT(G$1, ""ddd""), hour, LOOKUP(2, 1/($A23<>""""), $A23), type_A, $A$1, list_data, IFERROR(FILTER({'リスト'!$E$4:$F142, 'リスト'!$O$4:$P142}, ('リスト'!$A$4:$A142=day)*('リスト'!$B$4:$B142=hour)*(('リスト'!$G$4:$G142=""毎週配信"")+('リスト'!$G$4:$G14"&"2=type_A))), {"""","""","""",""""}), new_data, IFERROR(FILTER({'新規'!$E$2:$F142, '新規'!$O$2:$P142}, ('新規'!$A$2:$A142=G$1)*('新規'!$B$2:$B142=hour)), {"""","""","""",""""}), special_data, IFERROR(FILTER({'特殊配信マスタ'!$E$2:$F142, '特殊配信マスタ'!$O$2:$P142}, ('特殊配信マ"&"スタ'!$A$2:$A142=day)*('特殊配信マスタ'!$B$2:$B142=hour)*('特殊配信マスタ'!$R$2:$R142='特殊配信マスタ'!$S$2:$S142)), {"""","""","""",""""}), combined, VSTACK(list_data, new_data, special_data), FILTER(combined, INDEX(combined, , 1)<>"""", INDEX(combined, , 1)<>0) ), """")"),"40代未経験_正社員") -> 40代未経験_正社員 | H23: =IFERROR(__xludf.DUMMYFUNCTION("""COMPUTED_VALUE"""),2.3) -> 2.3 | I23: =IFERROR(__xludf.DUMMYFUNCTION("""COMPUTED_VALUE"""),"R") -> R | K23: =SUM(H23:H32) -> 3.9 | L23: =IFERROR(__xludf.DUMMYFUNCTION("IFERROR(LET( day, TEXT(L$1, ""ddd""), hour, LOOKUP(2, 1/($A23<>""""), $A23), type_A, $A$1, list_data, IFERROR(FILTER({'リスト'!$E$4:$F142, 'リスト'!$O$4:$P142}, ('リスト'!$A$4:$A142=day)*('リスト'!$B$4:$B142=hour)*(('リスト'!$G$4:$G142=""毎週配信"")+('リスト'!$G$4:$G14"&"2=type_A))), {"""","""","""",""""}), new_data, IFERROR(FILTER({'新規'!$E$2:$F142, '新規'!$O$2:$P142}, ('新規'!$A$2:$A142=L$1)*('新規'!$B$2:$B142=hour)), {"""","""","""",""""}), special_data, IFERROR(FILTER({'特殊配信マスタ'!$E$2:$F142, '特殊配信マスタ'!$O$2:$P142}, ('特殊配信マ"&"スタ'!$A$2:$A142=day)*('特殊配信マスタ'!$B$2:$B142=hour)*('特殊配信マスタ'!$R$2:$R142='特殊配信マスタ'!$S$2:$S142)), {"""","""","""",""""}), combined, VSTACK(list_data, new_data, special_data), FILTER(combined, INDEX(combined, , 1)<>"""", INDEX(combined, , 1)<>0) ), """")"),"フルリモートランキング") -> フルリモートランキング | M23: =IFERROR(__xludf.DUMMYFUNCTION("""COMPUTED_VALUE"""),0.5) -> 0.5 | N23: =IFERROR(__xludf.DUMMYFUNCTION("""COMPUTED_VALUE"""),"R") -> R | P23: =SUM(M23:M32) -> 6.9 | Q23: =IFERROR(__xludf.DUMMYFUNCTION("IFERROR(LET( day, TEXT(Q$1, ""ddd""), hour, LOOKUP(2, 1/($A23<>""""), $A23), type_A, $A$1, list_data, IFERROR(FILTER({'リスト'!$E$4:$F142, 'リスト'!$O$4:$P142}, ('リスト'!$A$4:$A142=day)*('リスト'!$B$4:$B142=hour)*(('リスト'!$G$4:$G142=""毎週配信"")+('リスト'!$G$4:$G14"&"2=type_A))), {"""","""","""",""""}), new_data, IFERROR(FILTER({'新規'!$E$2:$F142, '新規'!$O$2:$P142}, ('新規'!$A$2:$A142=Q$1)*('新規'!$B$2:$B142=hour)), {"""","""","""",""""}), special_data, IFERROR(FILTER({'特殊配信マスタ'!$E$2:$F142, '特殊配信マスタ'!$O$2:$P142}, ('特殊配信マ"&"スタ'!$A$2:$A142=day)*('特殊配信マスタ'!$B$2:$B142=hour)*('特殊配信マスタ'!$R$2:$R142='特殊配信マスタ'!$S$2:$S142)), {"""","""","""",""""}), combined, VSTACK(list_data, new_data, special_data), FILTER(combined, INDEX(combined, , 1)<>"""", INDEX(combined, , 1)<>0) ), """")"),"子育手当") -> 子育手当 | R23: =IFERROR(__xludf.DUMMYFUNCTION("""COMPUTED_VALUE"""),0.6) -> 0.6 | S23: =IFERROR(__xludf.DUMMYFUNCTION("""COMPUTED_VALUE"""),"R") -> R | U23: =SUM(R23:R32) -> 0.6 | V23: =IFERROR(__xludf.DUMMYFUNCTION("IFERROR(LET( day, TEXT(V$1, ""ddd""), hour, LOOKUP(2, 1/($A23<>""""), $A23), type_A, $A$1, list_data, IFERROR(FILTER({'リスト'!$E$4:$F142, 'リスト'!$O$4:$P142}, ('リスト'!$A$4:$A142=day)*('リスト'!$B$4:$B142=hour)*(('リスト'!$G$4:$G142=""毎週配信"")+('リスト'!$G$4:$G14"&"2=type_A))), {"""","""","""",""""}), new_data, IFERROR(FILTER({'新規'!$E$2:$F142, '新規'!$O$2:$P142}, ('新規'!$A$2:$A142=V$1)*('新規'!$B$2:$B142=hour)), {"""","""","""",""""}), special_data, IFERROR(FILTER({'特殊配信マスタ'!$E$2:$F142, '特殊配信マスタ'!$O$2:$P142}, ('特殊配信マ"&"スタ'!$A$2:$A142=day)*('特殊配信マスタ'!$B$2:$B142=hour)*('特殊配信マスタ'!$R$2:$R142='特殊配信マスタ'!$S$2:$S142)), {"""","""","""",""""}), combined, VSTACK(list_data, new_data, special_data), FILTER(combined, INDEX(combined, , 1)<>"""", INDEX(combined, , 1)<>0) ), """")"),"検討中ランキング_事務") -> 検討中ランキング_事務 | W23: =IFERROR(__xludf.DUMMYFUNCTION("""COMPUTED_VALUE"""),0.9) -> 0.9 | X23: =IFERROR(__xludf.DUMMYFUNCTION("""COMPUTED_VALUE"""),"R") -> R | Z23: =SUM(W23:W32) -> 2.9 | AA23: =IFERROR(__xludf.DUMMYFUNCTION("IFERROR(LET( day, TEXT(AA$1, ""ddd""), hour, LOOKUP(2, 1/($A23<>""""), $A23), type_A, $A$1, list_data, IFERROR(FILTER({'リスト'!$E$4:$F142, 'リスト'!$O$4:$P142}, ('リスト'!$A$4:$A142=day)*('リスト'!$B$4:$B142=hour)*(('リスト'!$G$4:$G142=""毎週配信"")+('リスト'!$G$4:$G1"&"42=type_A))), {"""","""","""",""""}), new_data, IFERROR(FILTER({'新規'!$E$2:$F142, '新規'!$O$2:$P142}, ('新規'!$A$2:$A142=AA$1)*('新規'!$B$2:$B142=hour)), {"""","""","""",""""}), special_data, IFERROR(FILTER({'特殊配信マスタ'!$E$2:$F142, '特殊配信マスタ'!$O$2:$P142}, ('特殊配"&"信マスタ'!$A$2:$A142=day)*('特殊配信マスタ'!$B$2:$B142=hour)*('特殊配信マスタ'!$R$2:$R142='特殊配信マスタ'!$S$2:$S142)), {"""","""","""",""""}), combined, VSTACK(list_data, new_data, special_data), FILTER(combined, INDEX(combined, , 1)<>"""", INDEX(combined, , 1)<>0) ), """")"),"語学を活かせる") -> 語学を活かせる | AB23: =IFERROR(__xludf.DUMMYFUNCTION("""COMPUTED_VALUE"""),0.4) -> 0.4 | AC23: =IFERROR(__xludf.DUMMYFUNCTION("""COMPUTED_VALUE"""),"R") -> R | AE23: =SUM(AB23:AB32) -> 0.4 | AF23: =IFERROR(__xludf.DUMMYFUNCTION("IFERROR(LET( day, TEXT(AF$1, ""ddd""), hour, LOOKUP(2, 1/($A23<>""""), $A23), type_A, $A$1, list_data, IFERROR(FILTER({'リスト'!$E$4:$F142, 'リスト'!$O$4:$P142}, ('リスト'!$A$4:$A142=day)*('リスト'!$B$4:$B142=hour)*(('リスト'!$G$4:$G142=""毎週配信"")+('リスト'!$G$4:$G1"&"42=type_A))), {"""","""","""",""""}), new_data, IFERROR(FILTER({'新規'!$E$2:$F142, '新規'!$O$2:$P142}, ('新規'!$A$2:$A142=AF$1)*('新規'!$B$2:$B142=hour)), {"""","""","""",""""}), special_data, IFERROR(FILTER({'特殊配信マスタ'!$E$2:$F142, '特殊配信マスタ'!$O$2:$P142}, ('特殊配"&"信マスタ'!$A$2:$A142=day)*('特殊配信マスタ'!$B$2:$B142=hour)*('特殊配信マスタ'!$R$2:$R142='特殊配信マスタ'!$S$2:$S142)), {"""","""","""",""""}), combined, VSTACK(list_data, new_data, special_data), FILTER(combined, INDEX(combined, , 1)<>"""", INDEX(combined, , 1)<>0) ), """")"),"☆TP部_事務_希望地") -> ☆TP部_事務_希望地 | AG23: =IFERROR(__xludf.DUMMYFUNCTION("""COMPUTED_VALUE"""),3.6) -> 3.6 | AH23: =IFERROR(__xludf.DUMMYFUNCTION("""COMPUTED_VALUE"""),"部") -> 部 | AI23: =IFERROR(__xludf.DUMMYFUNCTION("""COMPUTED_VALUE"""),"石") -> 石 | AJ23: =SUM(AG23:AG32) -> 3.6
B24: =IFERROR(__xludf.DUMMYFUNCTION("""COMPUTED_VALUE"""),"面接1回") -> 面接1回 | C24: =IFERROR(__xludf.DUMMYFUNCTION("""COMPUTED_VALUE"""),1.5) -> 1.5 | D24: =IFERROR(__xludf.DUMMYFUNCTION("""COMPUTED_VALUE"""),"R") -> R | G24: =IFERROR(__xludf.DUMMYFUNCTION("""COMPUTED_VALUE"""),"子育て支援") -> 子育て支援 | H24: =IFERROR(__xludf.DUMMYFUNCTION("""COMPUTED_VALUE"""),0.6) -> 0.6 | I24: =IFERROR(__xludf.DUMMYFUNCTION("""COMPUTED_VALUE"""),"R") -> R | L24: =IFERROR(__xludf.DUMMYFUNCTION("""COMPUTED_VALUE"""),"経験活かせる_営業") -> 経験活かせる_営業 | M24: =IFERROR(__xludf.DUMMYFUNCTION("""COMPUTED_VALUE"""),0.6) -> 0.6 | N24: =IFERROR(__xludf.DUMMYFUNCTION("""COMPUTED_VALUE"""),"R") -> R | V24: =IFERROR(__xludf.DUMMYFUNCTION("""COMPUTED_VALUE"""),"JAD特集") -> JAD特集 | W24: =IFERROR(__xludf.DUMMYFUNCTION("""COMPUTED_VALUE"""),2.0) -> 2
B25: =IFERROR(__xludf.DUMMYFUNCTION("""COMPUTED_VALUE"""),"面接1回_35歳以上") -> 面接1回_35歳以上 | C25: =IFERROR(__xludf.DUMMYFUNCTION("""COMPUTED_VALUE"""),1.0) -> 1 | D25: =IFERROR(__xludf.DUMMYFUNCTION("""COMPUTED_VALUE"""),"R") -> R | G25: =IFERROR(__xludf.DUMMYFUNCTION("""COMPUTED_VALUE"""),"趣味・興味メルマガ_A") -> 趣味・興味メルマガ_A | H25: =IFERROR(__xludf.DUMMYFUNCTION("""COMPUTED_VALUE"""),1.0) -> 1 | I25: =IFERROR(__xludf.DUMMYFUNCTION("""COMPUTED_VALUE"""),"R") -> R | L25: =IFERROR(__xludf.DUMMYFUNCTION("""COMPUTED_VALUE"""),"経験活かせる_事務") -> 経験活かせる_事務 | M25: =IFERROR(__xludf.DUMMYFUNCTION("""COMPUTED_VALUE"""),1.4) -> 1.4 | N25: =IFERROR(__xludf.DUMMYFUNCTION("""COMPUTED_VALUE"""),"R") -> R
L26: =IFERROR(__xludf.DUMMYFUNCTION("""COMPUTED_VALUE"""),"副業OK") -> 副業OK | M26: =IFERROR(__xludf.DUMMYFUNCTION("""COMPUTED_VALUE"""),4.4) -> 4.4 | N26: =IFERROR(__xludf.DUMMYFUNCTION("""COMPUTED_VALUE"""),"R") -> R
A33: =A23+1 -> 11 | B33: =IFERROR(__xludf.DUMMYFUNCTION("IFERROR(LET( day, TEXT(B$1, ""ddd""), hour, LOOKUP(2, 1/($A33<>""""), $A33), type_A, $A$1, list_data, IFERROR(FILTER({'リスト'!$E$4:$F142, 'リスト'!$O$4:$P142}, ('リスト'!$A$4:$A142=day)*('リスト'!$B$4:$B142=hour)*(('リスト'!$G$4:$G142=""毎週配信"")+('リスト'!$G$4:$G14"&"2=type_A))), {"""","""","""",""""}), new_data, IFERROR(FILTER({'新規'!$E$2:$F142, '新規'!$O$2:$P142}, ('新規'!$A$2:$A142=B$1)*('新規'!$B$2:$B142=hour)), {"""","""","""",""""}), special_data, IFERROR(FILTER({'特殊配信マスタ'!$E$2:$F142, '特殊配信マスタ'!$O$2:$P142}, ('特殊配信マ"&"スタ'!$A$2:$A142=day)*('特殊配信マスタ'!$B$2:$B142=hour)*('特殊配信マスタ'!$R$2:$R142='特殊配信マスタ'!$S$2:$S142)), {"""","""","""",""""}), combined, VSTACK(list_data, new_data, special_data), FILTER(combined, INDEX(combined, , 1)<>"""", INDEX(combined, , 1)<>0) ), """")"),"事務（経理）_希望") -> 事務（経理）_希望 | C33: =IFERROR(__xludf.DUMMYFUNCTION("""COMPUTED_VALUE"""),0.5) -> 0.5 | D33: =IFERROR(__xludf.DUMMYFUNCTION("""COMPUTED_VALUE"""),"R") -> R | F33: =SUM(C33:C42) -> 0.5 | G33: =IFERROR(__xludf.DUMMYFUNCTION("IFERROR(LET( day, TEXT(G$1, ""ddd""), hour, LOOKUP(2, 1/($A33<>""""), $A33), type_A, $A$1, list_data, IFERROR(FILTER({'リスト'!$E$4:$F142, 'リスト'!$O$4:$P142}, ('リスト'!$A$4:$A142=day)*('リスト'!$B$4:$B142=hour)*(('リスト'!$G$4:$G142=""毎週配信"")+('リスト'!$G$4:$G14"&"2=type_A))), {"""","""","""",""""}), new_data, IFERROR(FILTER({'新規'!$E$2:$F142, '新規'!$O$2:$P142}, ('新規'!$A$2:$A142=G$1)*('新規'!$B$2:$B142=hour)), {"""","""","""",""""}), special_data, IFERROR(FILTER({'特殊配信マスタ'!$E$2:$F142, '特殊配信マスタ'!$O$2:$P142}, ('特殊配信マ"&"スタ'!$A$2:$A142=day)*('特殊配信マスタ'!$B$2:$B142=hour)*('特殊配信マスタ'!$R$2:$R142='特殊配信マスタ'!$S$2:$S142)), {"""","""","""",""""}), combined, VSTACK(list_data, new_data, special_data), FILTER(combined, INDEX(combined, , 1)<>"""", INDEX(combined, , 1)<>0) ), """")"),"事務（総務・人事）_希望") -> 事務（総務・人事）_希望 | H33: =IFERROR(__xludf.DUMMYFUNCTION("""COMPUTED_VALUE"""),1.1) -> 1.1 | I33: =IFERROR(__xludf.DUMMYFUNCTION("""COMPUTED_VALUE"""),"R") -> R | K33: =SUM(H33:H42) -> 1.1 | L33: =IFERROR(__xludf.DUMMYFUNCTION("IFERROR(LET( day, TEXT(L$1, ""ddd""), hour, LOOKUP(2, 1/($A33<>""""), $A33), type_A, $A$1, list_data, IFERROR(FILTER({'リスト'!$E$4:$F142, 'リスト'!$O$4:$P142}, ('リスト'!$A$4:$A142=day)*('リスト'!$B$4:$B142=hour)*(('リスト'!$G$4:$G142=""毎週配信"")+('リスト'!$G$4:$G14"&"2=type_A))), {"""","""","""",""""}), new_data, IFERROR(FILTER({'新規'!$E$2:$F142, '新規'!$O$2:$P142}, ('新規'!$A$2:$A142=L$1)*('新規'!$B$2:$B142=hour)), {"""","""","""",""""}), special_data, IFERROR(FILTER({'特殊配信マスタ'!$E$2:$F142, '特殊配信マスタ'!$O$2:$P142}, ('特殊配信マ"&"スタ'!$A$2:$A142=day)*('特殊配信マスタ'!$B$2:$B142=hour)*('特殊配信マスタ'!$R$2:$R142='特殊配信マスタ'!$S$2:$S142)), {"""","""","""",""""}), combined, VSTACK(list_data, new_data, special_data), FILTER(combined, INDEX(combined, , 1)<>"""", INDEX(combined, , 1)<>0) ), """")"),"クリエイティブ（Web）_希望") -> クリエイティブ（Web）_希望 | M33: =IFERROR(__xludf.DUMMYFUNCTION("""COMPUTED_VALUE"""),0.4) -> 0.4 | N33: =IFERROR(__xludf.DUMMYFUNCTION("""COMPUTED_VALUE"""),"R") -> R | P33: =SUM(M33:M42) -> 2.9 | Q33: =IFERROR(__xludf.DUMMYFUNCTION("IFERROR(LET( day, TEXT(Q$1, ""ddd""), hour, LOOKUP(2, 1/($A33<>""""), $A33), type_A, $A$1, list_data, IFERROR(FILTER({'リスト'!$E$4:$F142, 'リスト'!$O$4:$P142}, ('リスト'!$A$4:$A142=day)*('リスト'!$B$4:$B142=hour)*(('リスト'!$G$4:$G142=""毎週配信"")+('リスト'!$G$4:$G14"&"2=type_A))), {"""","""","""",""""}), new_data, IFERROR(FILTER({'新規'!$E$2:$F142, '新規'!$O$2:$P142}, ('新規'!$A$2:$A142=Q$1)*('新規'!$B$2:$B142=hour)), {"""","""","""",""""}), special_data, IFERROR(FILTER({'特殊配信マスタ'!$E$2:$F142, '特殊配信マスタ'!$O$2:$P142}, ('特殊配信マ"&"スタ'!$A$2:$A142=day)*('特殊配信マスタ'!$B$2:$B142=hour)*('特殊配信マスタ'!$R$2:$R142='特殊配信マスタ'!$S$2:$S142)), {"""","""","""",""""}), combined, VSTACK(list_data, new_data, special_data), FILTER(combined, INDEX(combined, , 1)<>"""", INDEX(combined, , 1)<>0) ), """")"),"クリエイティブ（その他）_希望") -> クリエイティブ（その他）_希望 | R33: =IFERROR(__xludf.DUMMYFUNCTION("""COMPUTED_VALUE"""),0.3) -> 0.3 | S33: =IFERROR(__xludf.DUMMYFUNCTION("""COMPUTED_VALUE"""),"R") -> R | U33: =SUM(R33:R42) -> 6.5 | V33: =IFERROR(__xludf.DUMMYFUNCTION("IFERROR(LET( day, TEXT(V$1, ""ddd""), hour, LOOKUP(2, 1/($A33<>""""), $A33), type_A, $A$1, list_data, IFERROR(FILTER({'リスト'!$E$4:$F142, 'リスト'!$O$4:$P142}, ('リスト'!$A$4:$A142=day)*('リスト'!$B$4:$B142=hour)*(('リスト'!$G$4:$G142=""毎週配信"")+('リスト'!$G$4:$G14"&"2=type_A))), {"""","""","""",""""}), new_data, IFERROR(FILTER({'新規'!$E$2:$F142, '新規'!$O$2:$P142}, ('新規'!$A$2:$A142=V$1)*('新規'!$B$2:$B142=hour)), {"""","""","""",""""}), special_data, IFERROR(FILTER({'特殊配信マスタ'!$E$2:$F142, '特殊配信マスタ'!$O$2:$P142}, ('特殊配信マ"&"スタ'!$A$2:$A142=day)*('特殊配信マスタ'!$B$2:$B142=hour)*('特殊配信マスタ'!$R$2:$R142='特殊配信マスタ'!$S$2:$S142)), {"""","""","""",""""}), combined, VSTACK(list_data, new_data, special_data), FILTER(combined, INDEX(combined, , 1)<>"""", INDEX(combined, , 1)<>0) ), """")"),"フレックス_ランキング") -> フレックス_ランキング | W33: =IFERROR(__xludf.DUMMYFUNCTION("""COMPUTED_VALUE"""),2.0) -> 2 | X33: =IFERROR(__xludf.DUMMYFUNCTION("""COMPUTED_VALUE"""),"石") -> 石 | Y33: =IFERROR(__xludf.DUMMYFUNCTION("""COMPUTED_VALUE"""),"福") -> 福 | Z33: =SUM(W33:W42) -> 2 | AA33: =IFERROR(__xludf.DUMMYFUNCTION("IFERROR(LET( day, TEXT(AA$1, ""ddd""), hour, LOOKUP(2, 1/($A33<>""""), $A33), type_A, $A$1, list_data, IFERROR(FILTER({'リスト'!$E$4:$F142, 'リスト'!$O$4:$P142}, ('リスト'!$A$4:$A142=day)*('リスト'!$B$4:$B142=hour)*(('リスト'!$G$4:$G142=""毎週配信"")+('リスト'!$G$4:$G1"&"42=type_A))), {"""","""","""",""""}), new_data, IFERROR(FILTER({'新規'!$E$2:$F142, '新規'!$O$2:$P142}, ('新規'!$A$2:$A142=AA$1)*('新規'!$B$2:$B142=hour)), {"""","""","""",""""}), special_data, IFERROR(FILTER({'特殊配信マスタ'!$E$2:$F142, '特殊配信マスタ'!$O$2:$P142}, ('特殊配"&"信マスタ'!$A$2:$A142=day)*('特殊配信マスタ'!$B$2:$B142=hour)*('特殊配信マスタ'!$R$2:$R142='特殊配信マスタ'!$S$2:$S142)), {"""","""","""",""""}), combined, VSTACK(list_data, new_data, special_data), FILTER(combined, INDEX(combined, , 1)<>"""", INDEX(combined, , 1)<>0) ), """")"),"関西単独求人メルマガ_B") -> 関西単独求人メルマガ_B | AB33: =IFERROR(__xludf.DUMMYFUNCTION("""COMPUTED_VALUE"""),0.7) -> 0.7 | AC33: =IFERROR(__xludf.DUMMYFUNCTION("""COMPUTED_VALUE"""),"武") -> 武 | AD33: =IFERROR(__xludf.DUMMYFUNCTION("""COMPUTED_VALUE"""),"部") -> 部 | AE33: =SUM(AB33:AB42) -> 1.7 | AF33: =IFERROR(__xludf.DUMMYFUNCTION("IFERROR(LET( day, TEXT(AF$1, ""ddd""), hour, LOOKUP(2, 1/($A33<>""""), $A33), type_A, $A$1, list_data, IFERROR(FILTER({'リスト'!$E$4:$F142, 'リスト'!$O$4:$P142}, ('リスト'!$A$4:$A142=day)*('リスト'!$B$4:$B142=hour)*(('リスト'!$G$4:$G142=""毎週配信"")+('リスト'!$G$4:$G1"&"42=type_A))), {"""","""","""",""""}), new_data, IFERROR(FILTER({'新規'!$E$2:$F142, '新規'!$O$2:$P142}, ('新規'!$A$2:$A142=AF$1)*('新規'!$B$2:$B142=hour)), {"""","""","""",""""}), special_data, IFERROR(FILTER({'特殊配信マスタ'!$E$2:$F142, '特殊配信マスタ'!$O$2:$P142}, ('特殊配"&"信マスタ'!$A$2:$A142=day)*('特殊配信マスタ'!$B$2:$B142=hour)*('特殊配信マスタ'!$R$2:$R142='特殊配信マスタ'!$S$2:$S142)), {"""","""","""",""""}), combined, VSTACK(list_data, new_data, special_data), FILTER(combined, INDEX(combined, , 1)<>"""", INDEX(combined, , 1)<>0) ), """")"),"クリエイティブ総合ランキング") -> クリエイティブ総合ランキング | AG33: =IFERROR(__xludf.DUMMYFUNCTION("""COMPUTED_VALUE"""),0.8) -> 0.8 | AH33: =IFERROR(__xludf.DUMMYFUNCTION("""COMPUTED_VALUE"""),"R") -> R | AJ33: =SUM(AG33:AG42) -> 1.5
L34: =IFERROR(__xludf.DUMMYFUNCTION("""COMPUTED_VALUE"""),"コロナ禍_事務_首都圏") -> コロナ禍_事務_首都圏 | M34: =IFERROR(__xludf.DUMMYFUNCTION("""COMPUTED_VALUE"""),2.5) -> 2.5 | N34: =IFERROR(__xludf.DUMMYFUNCTION("""COMPUTED_VALUE"""),"R") -> R | Q34: =IFERROR(__xludf.DUMMYFUNCTION("""COMPUTED_VALUE"""),"今週の人気求人ランキング") -> 今週の人気求人ランキング | R34: =IFERROR(__xludf.DUMMYFUNCTION("""COMPUTED_VALUE"""),5.7) -> 5.7 | S34: =IFERROR(__xludf.DUMMYFUNCTION("""COMPUTED_VALUE"""),"R") -> R | AA34: =IFERROR(__xludf.DUMMYFUNCTION("""COMPUTED_VALUE"""),"事務（営業事務）_希望") -> 事務（営業事務）_希望 | AB34: =IFERROR(__xludf.DUMMYFUNCTION("""COMPUTED_VALUE"""),1.0) -> 1 | AC34: =IFERROR(__xludf.DUMMYFUNCTION("""COMPUTED_VALUE"""),"R") -> R | AF34: =IFERROR(__xludf.DUMMYFUNCTION("""COMPUTED_VALUE"""),"関西_未経験リモート_事務") -> 関西_未経験リモート_事務 | AG34: =IFERROR(__xludf.DUMMYFUNCTION("""COMPUTED_VALUE"""),0.7) -> 0.7 | AH34: =IFERROR(__xludf.DUMMYFUNCTION("""COMPUTED_VALUE"""),"R") -> R
Q35: =IFERROR(__xludf.DUMMYFUNCTION("""COMPUTED_VALUE"""),"事務（広報）_希望") -> 事務（広報）_希望 | R35: =IFERROR(__xludf.DUMMYFUNCTION("""COMPUTED_VALUE"""),0.5) -> 0.5 | S35: =IFERROR(__xludf.DUMMYFUNCTION("""COMPUTED_VALUE"""),"R") -> R
A43: =A33+1 -> 12 | B43: =IFERROR(__xludf.DUMMYFUNCTION("IFERROR(LET( day, TEXT(B$1, ""ddd""), hour, LOOKUP(2, 1/($A43<>""""), $A43), type_A, $A$1, list_data, IFERROR(FILTER({'リスト'!$E$4:$F142, 'リスト'!$O$4:$P142}, ('リスト'!$A$4:$A142=day)*('リスト'!$B$4:$B142=hour)*(('リスト'!$G$4:$G142=""毎週配信"")+('リスト'!$G$4:$G14"&"2=type_A))), {"""","""","""",""""}), new_data, IFERROR(FILTER({'新規'!$E$2:$F142, '新規'!$O$2:$P142}, ('新規'!$A$2:$A142=B$1)*('新規'!$B$2:$B142=hour)), {"""","""","""",""""}), special_data, IFERROR(FILTER({'特殊配信マスタ'!$E$2:$F142, '特殊配信マスタ'!$O$2:$P142}, ('特殊配信マ"&"スタ'!$A$2:$A142=day)*('特殊配信マスタ'!$B$2:$B142=hour)*('特殊配信マスタ'!$R$2:$R142='特殊配信マスタ'!$S$2:$S142)), {"""","""","""",""""}), combined, VSTACK(list_data, new_data, special_data), FILTER(combined, INDEX(combined, , 1)<>"""", INDEX(combined, , 1)<>0) ), """")"),"★新着総合_首都圏 A") -> ★新着総合_首都圏 A | C43: =IFERROR(__xludf.DUMMYFUNCTION("""COMPUTED_VALUE"""),5.0) -> 5 | D43: =IFERROR(__xludf.DUMMYFUNCTION("""COMPUTED_VALUE"""),"荒") -> 荒 | E43: =IFERROR(__xludf.DUMMYFUNCTION("""COMPUTED_VALUE"""),"平") -> 平 | F43: =SUM(C43:C52) -> 10.4 | G43: =IFERROR(__xludf.DUMMYFUNCTION("IFERROR(LET( day, TEXT(G$1, ""ddd""), hour, LOOKUP(2, 1/($A43<>""""), $A43), type_A, $A$1, list_data, IFERROR(FILTER({'リスト'!$E$4:$F142, 'リスト'!$O$4:$P142}, ('リスト'!$A$4:$A142=day)*('リスト'!$B$4:$B142=hour)*(('リスト'!$G$4:$G142=""毎週配信"")+('リスト'!$G$4:$G14"&"2=type_A))), {"""","""","""",""""}), new_data, IFERROR(FILTER({'新規'!$E$2:$F142, '新規'!$O$2:$P142}, ('新規'!$A$2:$A142=G$1)*('新規'!$B$2:$B142=hour)), {"""","""","""",""""}), special_data, IFERROR(FILTER({'特殊配信マスタ'!$E$2:$F142, '特殊配信マスタ'!$O$2:$P142}, ('特殊配信マ"&"スタ'!$A$2:$A142=day)*('特殊配信マスタ'!$B$2:$B142=hour)*('特殊配信マスタ'!$R$2:$R142='特殊配信マスタ'!$S$2:$S142)), {"""","""","""",""""}), combined, VSTACK(list_data, new_data, special_data), FILTER(combined, INDEX(combined, , 1)<>"""", INDEX(combined, , 1)<>0) ), """")"),"自己PR不要_リモート未経験_事務") -> 自己PR不要_リモート未経験_事務 | H43: =IFERROR(__xludf.DUMMYFUNCTION("""COMPUTED_VALUE"""),2.5) -> 2.5 | I43: =IFERROR(__xludf.DUMMYFUNCTION("""COMPUTED_VALUE"""),"R") -> R | K43: =SUM(H43:H52) -> 6.7 | L43: =IFERROR(__xludf.DUMMYFUNCTION("IFERROR(LET( day, TEXT(L$1, ""ddd""), hour, LOOKUP(2, 1/($A43<>""""), $A43), type_A, $A$1, list_data, IFERROR(FILTER({'リスト'!$E$4:$F142, 'リスト'!$O$4:$P142}, ('リスト'!$A$4:$A142=day)*('リスト'!$B$4:$B142=hour)*(('リスト'!$G$4:$G142=""毎週配信"")+('リスト'!$G$4:$G14"&"2=type_A))), {"""","""","""",""""}), new_data, IFERROR(FILTER({'新規'!$E$2:$F142, '新規'!$O$2:$P142}, ('新規'!$A$2:$A142=L$1)*('新規'!$B$2:$B142=hour)), {"""","""","""",""""}), special_data, IFERROR(FILTER({'特殊配信マスタ'!$E$2:$F142, '特殊配信マスタ'!$O$2:$P142}, ('特殊配信マ"&"スタ'!$A$2:$A142=day)*('特殊配信マスタ'!$B$2:$B142=hour)*('特殊配信マスタ'!$R$2:$R142='特殊配信マスタ'!$S$2:$S142)), {"""","""","""",""""}), combined, VSTACK(list_data, new_data, special_data), FILTER(combined, INDEX(combined, , 1)<>"""", INDEX(combined, , 1)<>0) ), """")"),"応募ランキング B") -> 応募ランキング B | M43: =IFERROR(__xludf.DUMMYFUNCTION("""COMPUTED_VALUE"""),3.5) -> 3.5 | N43: =IFERROR(__xludf.DUMMYFUNCTION("""COMPUTED_VALUE"""),"R") -> R | P43: =SUM(M43:M52) -> 8.3 | Q43: =IFERROR(__xludf.DUMMYFUNCTION("IFERROR(LET( day, TEXT(Q$1, ""ddd""), hour, LOOKUP(2, 1/($A43<>""""), $A43), type_A, $A$1, list_data, IFERROR(FILTER({'リスト'!$E$4:$F142, 'リスト'!$O$4:$P142}, ('リスト'!$A$4:$A142=day)*('リスト'!$B$4:$B142=hour)*(('リスト'!$G$4:$G142=""毎週配信"")+('リスト'!$G$4:$G14"&"2=type_A))), {"""","""","""",""""}), new_data, IFERROR(FILTER({'新規'!$E$2:$F142, '新規'!$O$2:$P142}, ('新規'!$A$2:$A142=Q$1)*('新規'!$B$2:$B142=hour)), {"""","""","""",""""}), special_data, IFERROR(FILTER({'特殊配信マスタ'!$E$2:$F142, '特殊配信マスタ'!$O$2:$P142}, ('特殊配信マ"&"スタ'!$A$2:$A142=day)*('特殊配信マスタ'!$B$2:$B142=hour)*('特殊配信マスタ'!$R$2:$R142='特殊配信マスタ'!$S$2:$S142)), {"""","""","""",""""}), combined, VSTACK(list_data, new_data, special_data), FILTER(combined, INDEX(combined, , 1)<>"""", INDEX(combined, , 1)<>0) ), """")"),"★新着総合_首都圏 B") -> ★新着総合_首都圏 B | R43: =IFERROR(__xludf.DUMMYFUNCTION("""COMPUTED_VALUE"""),5.0) -> 5 | S43: =IFERROR(__xludf.DUMMYFUNCTION("""COMPUTED_VALUE"""),"荒") -> 荒 | T43: =IFERROR(__xludf.DUMMYFUNCTION("""COMPUTED_VALUE"""),"平") -> 平 | U43: =SUM(R43:R52) -> 10.4 | V43: =IFERROR(__xludf.DUMMYFUNCTION("IFERROR(LET( day, TEXT(V$1, ""ddd""), hour, LOOKUP(2, 1/($A43<>""""), $A43), type_A, $A$1, list_data, IFERROR(FILTER({'リスト'!$E$4:$F142, 'リスト'!$O$4:$P142}, ('リスト'!$A$4:$A142=day)*('リスト'!$B$4:$B142=hour)*(('リスト'!$G$4:$G142=""毎週配信"")+('リスト'!$G$4:$G14"&"2=type_A))), {"""","""","""",""""}), new_data, IFERROR(FILTER({'新規'!$E$2:$F142, '新規'!$O$2:$P142}, ('新規'!$A$2:$A142=V$1)*('新規'!$B$2:$B142=hour)), {"""","""","""",""""}), special_data, IFERROR(FILTER({'特殊配信マスタ'!$E$2:$F142, '特殊配信マスタ'!$O$2:$P142}, ('特殊配信マ"&"スタ'!$A$2:$A142=day)*('特殊配信マスタ'!$B$2:$B142=hour)*('特殊配信マスタ'!$R$2:$R142='特殊配信マスタ'!$S$2:$S142)), {"""","""","""",""""}), combined, VSTACK(list_data, new_data, special_data), FILTER(combined, INDEX(combined, , 1)<>"""", INDEX(combined, , 1)<>0) ), """")"),"高層ビルで働く_首都圏") -> 高層ビルで働く_首都圏 | W43: =IFERROR(__xludf.DUMMYFUNCTION("""COMPUTED_VALUE"""),1.6) -> 1.6 | X43: =IFERROR(__xludf.DUMMYFUNCTION("""COMPUTED_VALUE"""),"部") -> 部 | Y43: =IFERROR(__xludf.DUMMYFUNCTION("""COMPUTED_VALUE"""),"石") -> 石 | Z43: =SUM(W43:W52) -> 3.1 | AA43: =IFERROR(__xludf.DUMMYFUNCTION("IFERROR(LET( day, TEXT(AA$1, ""ddd""), hour, LOOKUP(2, 1/($A43<>""""), $A43), type_A, $A$1, list_data, IFERROR(FILTER({'リスト'!$E$4:$F142, 'リスト'!$O$4:$P142}, ('リスト'!$A$4:$A142=day)*('リスト'!$B$4:$B142=hour)*(('リスト'!$G$4:$G142=""毎週配信"")+('リスト'!$G$4:$G1"&"42=type_A))), {"""","""","""",""""}), new_data, IFERROR(FILTER({'新規'!$E$2:$F142, '新規'!$O$2:$P142}, ('新規'!$A$2:$A142=AA$1)*('新規'!$B$2:$B142=hour)), {"""","""","""",""""}), special_data, IFERROR(FILTER({'特殊配信マスタ'!$E$2:$F142, '特殊配信マスタ'!$O$2:$P142}, ('特殊配"&"信マスタ'!$A$2:$A142=day)*('特殊配信マスタ'!$B$2:$B142=hour)*('特殊配信マスタ'!$R$2:$R142='特殊配信マスタ'!$S$2:$S142)), {"""","""","""",""""}), combined, VSTACK(list_data, new_data, special_data), FILTER(combined, INDEX(combined, , 1)<>"""", INDEX(combined, , 1)<>0) ), """")"),"★ウキポリ[全]") -> ★ウキポリ[全] | AB43: =IFERROR(__xludf.DUMMYFUNCTION("""COMPUTED_VALUE"""),10.0) -> 10 | AC43: =IFERROR(__xludf.DUMMYFUNCTION("""COMPUTED_VALUE"""),"平") -> 平 | AD43: =IFERROR(__xludf.DUMMYFUNCTION("""COMPUTED_VALUE"""),"荒") -> 荒 | AE43: =SUM(AB43:AB52) -> 10 | AF43: =IFERROR(__xludf.DUMMYFUNCTION("IFERROR(LET( day, TEXT(AF$1, ""ddd""), hour, LOOKUP(2, 1/($A43<>""""), $A43), type_A, $A$1, list_data, IFERROR(FILTER({'リスト'!$E$4:$F142, 'リスト'!$O$4:$P142}, ('リスト'!$A$4:$A142=day)*('リスト'!$B$4:$B142=hour)*(('リスト'!$G$4:$G142=""毎週配信"")+('リスト'!$G$4:$G1"&"42=type_A))), {"""","""","""",""""}), new_data, IFERROR(FILTER({'新規'!$E$2:$F142, '新規'!$O$2:$P142}, ('新規'!$A$2:$A142=AF$1)*('新規'!$B$2:$B142=hour)), {"""","""","""",""""}), special_data, IFERROR(FILTER({'特殊配信マスタ'!$E$2:$F142, '特殊配信マスタ'!$O$2:$P142}, ('特殊配"&"信マスタ'!$A$2:$A142=day)*('特殊配信マスタ'!$B$2:$B142=hour)*('特殊配信マスタ'!$R$2:$R142='特殊配信マスタ'!$S$2:$S142)), {"""","""","""",""""}), combined, VSTACK(list_data, new_data, special_data), FILTER(combined, INDEX(combined, , 1)<>"""", INDEX(combined, , 1)<>0) ), """")"),"未経験OK_専門性の高い事務") -> 未経験OK_専門性の高い事務 | AG43: =IFERROR(__xludf.DUMMYFUNCTION("""COMPUTED_VALUE"""),1.4) -> 1.4 | AH43: =IFERROR(__xludf.DUMMYFUNCTION("""COMPUTED_VALUE"""),"部") -> 部 | AI43: =IFERROR(__xludf.DUMMYFUNCTION("""COMPUTED_VALUE"""),"石") -> 石 | AJ43: =SUM(AG43:AG52) -> 8.4
B44: =IFERROR(__xludf.DUMMYFUNCTION("""COMPUTED_VALUE"""),"★新着総合_西日本 A") -> ★新着総合_西日本 A | C44: =IFERROR(__xludf.DUMMYFUNCTION("""COMPUTED_VALUE"""),2.9) -> 2.9 | D44: =IFERROR(__xludf.DUMMYFUNCTION("""COMPUTED_VALUE"""),"荒") -> 荒 | E44: =IFERROR(__xludf.DUMMYFUNCTION("""COMPUTED_VALUE"""),"平") -> 平 | G44: =IFERROR(__xludf.DUMMYFUNCTION("""COMPUTED_VALUE"""),"自己PR不要_リモート未経験_営業") -> 自己PR不要_リモート未経験_営業 | H44: =IFERROR(__xludf.DUMMYFUNCTION("""COMPUTED_VALUE"""),0.3) -> 0.3 | I44: =IFERROR(__xludf.DUMMYFUNCTION("""COMPUTED_VALUE"""),"R") -> R | L44: =IFERROR(__xludf.DUMMYFUNCTION("""COMPUTED_VALUE"""),"応募ランキングB_全国") -> 応募ランキングB_全国 | M44: =IFERROR(__xludf.DUMMYFUNCTION("""COMPUTED_VALUE"""),3.4) -> 3.4 | N44: =IFERROR(__xludf.DUMMYFUNCTION("""COMPUTED_VALUE"""),"R") -> R | Q44: =IFERROR(__xludf.DUMMYFUNCTION("""COMPUTED_VALUE"""),"★新着総合_西日本 B") -> ★新着総合_西日本 B | R44: =IFERROR(__xludf.DUMMYFUNCTION("""COMPUTED_VALUE"""),2.9) -> 2.9 | S44: =IFERROR(__xludf.DUMMYFUNCTION("""COMPUTED_VALUE"""),"荒") -> 荒 | T44: =IFERROR(__xludf.DUMMYFUNCTION("""COMPUTED_VALUE"""),"平") -> 平 | V44: =IFERROR(__xludf.DUMMYFUNCTION("""COMPUTED_VALUE"""),"高層ビルで働く_大阪") -> 高層ビルで働く_大阪 | W44: =IFERROR(__xludf.DUMMYFUNCTION("""COMPUTED_VALUE"""),0.5) -> 0.5 | X44: =IFERROR(__xludf.DUMMYFUNCTION("""COMPUTED_VALUE"""),"部") -> 部 | Y44: =IFERROR(__xludf.DUMMYFUNCTION("""COMPUTED_VALUE"""),"石") -> 石 | AF44: =IFERROR(__xludf.DUMMYFUNCTION("""COMPUTED_VALUE"""),"★納品対策") -> ★納品対策 | AG44: =IFERROR(__xludf.DUMMYFUNCTION("""COMPUTED_VALUE"""),7.0) -> 7 | AH44: =IFERROR(__xludf.DUMMYFUNCTION("""COMPUTED_VALUE"""),"平") -> 平 | AI44: =IFERROR(__xludf.DUMMYFUNCTION("""COMPUTED_VALUE"""),"荒") -> 荒
B45: =IFERROR(__xludf.DUMMYFUNCTION("""COMPUTED_VALUE"""),"★新着総合_東海 A") -> ★新着総合_東海 A | C45: =IFERROR(__xludf.DUMMYFUNCTION("""COMPUTED_VALUE"""),1.0) -> 1 | D45: =IFERROR(__xludf.DUMMYFUNCTION("""COMPUTED_VALUE"""),"荒") -> 荒 | E45: =IFERROR(__xludf.DUMMYFUNCTION("""COMPUTED_VALUE"""),"平") -> 平 | G45: =IFERROR(__xludf.DUMMYFUNCTION("""COMPUTED_VALUE"""),"自己PR不要_残業無_未経験_販サ") -> 自己PR不要_残業無_未経験_販サ | H45: =IFERROR(__xludf.DUMMYFUNCTION("""COMPUTED_VALUE"""),0.3) -> 0.3 | I45: =IFERROR(__xludf.DUMMYFUNCTION("""COMPUTED_VALUE"""),"R") -> R | L45: =IFERROR(__xludf.DUMMYFUNCTION("""COMPUTED_VALUE"""),"丸の内・大手町・有楽町_残業少_事務 ") -> 丸の内・大手町・有楽町_残業少_事務 | M45: =IFERROR(__xludf.DUMMYFUNCTION("""COMPUTED_VALUE"""),0.9) -> 0.9 | N45: =IFERROR(__xludf.DUMMYFUNCTION("""COMPUTED_VALUE"""),"R") -> R | Q45: =IFERROR(__xludf.DUMMYFUNCTION("""COMPUTED_VALUE"""),"★新着総合_東海 B") -> ★新着総合_東海 B | R45: =IFERROR(__xludf.DUMMYFUNCTION("""COMPUTED_VALUE"""),1.0) -> 1 | S45: =IFERROR(__xludf.DUMMYFUNCTION("""COMPUTED_VALUE"""),"荒") -> 荒 | T45: =IFERROR(__xludf.DUMMYFUNCTION("""COMPUTED_VALUE"""),"平") -> 平 | V45: =IFERROR(__xludf.DUMMYFUNCTION("""COMPUTED_VALUE"""),"趣味・興味メルマガ_B") -> 趣味・興味メルマガ_B | W45: =IFERROR(__xludf.DUMMYFUNCTION("""COMPUTED_VALUE"""),1.0) -> 1 | X45: =IFERROR(__xludf.DUMMYFUNCTION("""COMPUTED_VALUE"""),"R") -> R
B46: =IFERROR(__xludf.DUMMYFUNCTION("""COMPUTED_VALUE"""),"★新着総合_北海道・東北 A") -> ★新着総合_北海道・東北 A | C46: =IFERROR(__xludf.DUMMYFUNCTION("""COMPUTED_VALUE"""),0.8) -> 0.8 | D46: =IFERROR(__xludf.DUMMYFUNCTION("""COMPUTED_VALUE"""),"荒") -> 荒 | E46: =IFERROR(__xludf.DUMMYFUNCTION("""COMPUTED_VALUE"""),"平") -> 平 | G46: =IFERROR(__xludf.DUMMYFUNCTION("""COMPUTED_VALUE"""),"自己PR不要_リモート未経験_エンジニア") -> 自己PR不要_リモート未経験_エンジニア | H46: =IFERROR(__xludf.DUMMYFUNCTION("""COMPUTED_VALUE"""),0.2) -> 0.2 | I46: =IFERROR(__xludf.DUMMYFUNCTION("""COMPUTED_VALUE"""),"R") -> R | L46: =IFERROR(__xludf.DUMMYFUNCTION("""COMPUTED_VALUE"""),"資格活かせる_簿記") -> 資格活かせる_簿記 | M46: =IFERROR(__xludf.DUMMYFUNCTION("""COMPUTED_VALUE"""),0.3) -> 0.3 | N46: =IFERROR(__xludf.DUMMYFUNCTION("""COMPUTED_VALUE"""),"R") -> R | Q46: =IFERROR(__xludf.DUMMYFUNCTION("""COMPUTED_VALUE"""),"★新着総合_北海道・東北 B") -> ★新着総合_北海道・東北 B | R46: =IFERROR(__xludf.DUMMYFUNCTION("""COMPUTED_VALUE"""),0.8) -> 0.8 | S46: =IFERROR(__xludf.DUMMYFUNCTION("""COMPUTED_VALUE"""),"荒") -> 荒 | T46: =IFERROR(__xludf.DUMMYFUNCTION("""COMPUTED_VALUE"""),"平") -> 平
B47: =IFERROR(__xludf.DUMMYFUNCTION("""COMPUTED_VALUE"""),"★新着総合_北関東・甲信越・北陸 A") -> ★新着総合_北関東・甲信越・北陸 A | C47: =IFERROR(__xludf.DUMMYFUNCTION("""COMPUTED_VALUE"""),0.7) -> 0.7 | D47: =IFERROR(__xludf.DUMMYFUNCTION("""COMPUTED_VALUE"""),"荒") -> 荒 | E47: =IFERROR(__xludf.DUMMYFUNCTION("""COMPUTED_VALUE"""),"平") -> 平 | G47: =IFERROR(__xludf.DUMMYFUNCTION("""COMPUTED_VALUE"""),"休日120日_就業中_関西") -> 休日120日_就業中_関西 | H47: =IFERROR(__xludf.DUMMYFUNCTION("""COMPUTED_VALUE"""),0.7) -> 0.7 | I47: =IFERROR(__xludf.DUMMYFUNCTION("""COMPUTED_VALUE"""),"R") -> R | L47: =IFERROR(__xludf.DUMMYFUNCTION("""COMPUTED_VALUE"""),"新規会員向け_自己PR不要_求人特集") -> 新規会員向け_自己PR不要_求人特集 | M47: =IFERROR(__xludf.DUMMYFUNCTION("""COMPUTED_VALUE"""),0.2) -> 0.2 | N47: =IFERROR(__xludf.DUMMYFUNCTION("""COMPUTED_VALUE"""),"R") -> R | Q47: =IFERROR(__xludf.DUMMYFUNCTION("""COMPUTED_VALUE"""),"★新着総合_北関東・甲信越・北陸 B") -> ★新着総合_北関東・甲信越・北陸 B | R47: =IFERROR(__xludf.DUMMYFUNCTION("""COMPUTED_VALUE"""),0.7) -> 0.7 | S47: =IFERROR(__xludf.DUMMYFUNCTION("""COMPUTED_VALUE"""),"荒") -> 荒 | T47: =IFERROR(__xludf.DUMMYFUNCTION("""COMPUTED_VALUE"""),"平") -> 平
G48: =IFERROR(__xludf.DUMMYFUNCTION("""COMPUTED_VALUE"""),"休日120日_未就業") -> 休日120日_未就業 | H48: =IFERROR(__xludf.DUMMYFUNCTION("""COMPUTED_VALUE"""),0.7) -> 0.7 | I48: =IFERROR(__xludf.DUMMYFUNCTION("""COMPUTED_VALUE"""),"R") -> R
G49: =IFERROR(__xludf.DUMMYFUNCTION("""COMPUTED_VALUE"""),"5月入社可能") -> 5月入社可能 | H49: =IFERROR(__xludf.DUMMYFUNCTION("""COMPUTED_VALUE"""),2.0) -> 2 | I49: =IFERROR(__xludf.DUMMYFUNCTION("""COMPUTED_VALUE"""),"石") -> 石 | J49: =IFERROR(__xludf.DUMMYFUNCTION("""COMPUTED_VALUE"""),"部") -> 部
